<?xml version="1.0" encoding="utf-8"?>
<!-- This URDF was automatically created by SolidWorks to URDF Exporter! Originally created by Stephen Brawner (brawner@gmail.com) 
     Commit Version: 1.6.0-1-g15f4949  Build Version: 1.6.7594.29634
     For more information, please see http://wiki.ros.org/sw_urdf_exporter -->
<robot
  name="LiteParallelGriper9">
  <link
    name="Link0">
    <inertial>
      <origin
        xyz="0.0187322287468848 -0.00183270076678829 6.5626838841288E-05"
        rpy="0 0 0" />
      <mass
        value="1.65199774001772" />
      <inertia
        ixx="0.00540779041066965"
        ixy="-8.16857492340903E-08"
        ixz="1.72431674672113E-07"
        iyy="0.00334480903849763"
        iyz="0.000338002907863305"
        izz="0.0050429459667963" />
    </inertial>
    <visual>
      <origin
        xyz="0 0 0"
        rpy="0 0 0" />
      <geometry>
        <mesh
          filename="package://LiteParallelGriper9/meshes/Link0.STL" />
      </geometry>
      <material
        name="">
        <color
          rgba="0.792156862745098 0.819607843137255 0.933333333333333 1" />
      </material>
    </visual>
    <collision>
      <origin
        xyz="0 0 0"
        rpy="0 0 0" />
      <geometry>
        <mesh
          filename="package://LiteParallelGriper9/meshes/Link0.STL" />
      </geometry>
    </collision>
  </link>
  <link
    name="Link1">
    <inertial>
      <origin
        xyz="0.0151275877640529 0.0579204989758781 2.29070547088858E-06"
        rpy="0 0 0" />
      <mass
        value="0.768987424503121" />
      <inertia
        ixx="0.000943620166744112"
        ixy="-0.000157292469488381"
        ixz="2.16151675811599E-07"
        iyy="0.00109494955205421"
        iyz="-2.22385109435551E-07"
        izz="0.00140822543505756" />
    </inertial>
    <visual>
      <origin
        xyz="0 0 0"
        rpy="0 0 0" />
      <geometry>
        <mesh
          filename="package://LiteParallelGriper9/meshes/Link1.STL" />
      </geometry>
      <material
        name="">
        <color
          rgba="0.792156862745098 0.819607843137255 0.933333333333333 1" />
      </material>
    </visual>
    <collision>
      <origin
        xyz="0 0 0"
        rpy="0 0 0" />
      <geometry>
        <mesh
          filename="package://LiteParallelGriper9/meshes/Link1.STL" />
      </geometry>
    </collision>
  </link>
  <joint
    name="Joint1"
    type="continuous">
    <origin
      xyz="0.01873370459204 0.00814213077337099 0.108012813287898"
      rpy="1.5707963267949 0 0.534566415064034" />
    <parent
      link="Link0" />
    <child
      link="Link1" />
    <axis
      xyz="0 1 0" />
    <limit
      lower="-3.14"
      upper="3.14"
      effort="87"
      velocity="0.5" />
  </joint>
  <link
    name="Link2">
    <inertial>
      <origin
        xyz="0.0319552717721059 0.114689324870814 -2.34165446214019E-07"
        rpy="0 0 0" />
      <mass
        value="1.07641455840455" />
      <inertia
        ixx="0.00746471638775654"
        ixy="0.000698716686025042"
        ixz="2.91962998048845E-10"
        iyy="0.00101418449701484"
        iyz="2.23314209243965E-08"
        izz="0.00762585101007418" />
    </inertial>
    <visual>
      <origin
        xyz="0 0 0"
        rpy="0 0 0" />
      <geometry>
        <mesh
          filename="package://LiteParallelGriper9/meshes/Link2.STL" />
      </geometry>
      <material
        name="">
        <color
          rgba="0.792156862745098 0.819607843137255 0.933333333333333 1" />
      </material>
    </visual>
    <collision>
      <origin
        xyz="0 0 0"
        rpy="0 0 0" />
      <geometry>
        <mesh
          filename="package://LiteParallelGriper9/meshes/Link2.STL" />
      </geometry>
    </collision>
  </link>
  <joint
    name="Joint2"
    type="continuous">
    <origin
      xyz="0.0708145360547446 0.0700027545006994 0"
      rpy="0.293075358022589 0 0" />
    <parent
      link="Link1" />
    <child
      link="Link2" />
    <axis
      xyz="1 0 0" />
    <limit
      lower="-3.14"
      upper="3.14"
      effort="87"
      velocity="0.5" />
  </joint>
  <link
    name="Link3">
    <inertial>
      <origin
        xyz="-0.0684079283978322 -0.0374546242809209 -0.00057322344864813"
        rpy="0 0 0" />
      <mass
        value="0.765154206506972" />
      <inertia
        ixx="0.00178431293310252"
        ixy="-9.39620212904799E-05"
        ixz="4.18851807630257E-06"
        iyy="0.000627171541037176"
        iyz="-6.64756261159853E-05"
        izz="0.00183655460550802" />
    </inertial>
    <visual>
      <origin
        xyz="0 0 0"
        rpy="0 0 0" />
      <geometry>
        <mesh
          filename="package://LiteParallelGriper9/meshes/Link3.STL" />
      </geometry>
      <material
        name="">
        <color
          rgba="0.792156862745098 0.819607843137255 0.933333333333333 1" />
      </material>
    </visual>
    <collision>
      <origin
        xyz="0 0 0"
        rpy="0 0 0" />
      <geometry>
        <mesh
          filename="package://LiteParallelGriper9/meshes/Link3.STL" />
      </geometry>
    </collision>
  </link>
  <joint
    name="Joint3"
    type="continuous">
    <origin
      xyz="0 0.199999999987175 0"
      rpy="-1.9165781011244 0 0" />
    <parent
      link="Link2" />
    <child
      link="Link3" />
    <axis
      xyz="1 0 0" />
    <limit
      lower="-3.14"
      upper="3.14"
      effort="87"
      velocity="0.5" />
  </joint>
  <link
    name="Link4">
    <inertial>
      <origin
        xyz="0.0251920450883915 -6.67161865794408E-07 -0.0963887898740919"
        rpy="0 0 0" />
      <mass
        value="1.19946345498765" />
      <inertia
        ixx="0.00242244328367107"
        ixy="-2.35680673095105E-08"
        ixz="0.000758522353835606"
        iyy="0.00315207302827081"
        iyz="3.85905844176623E-09"
        izz="0.0017276308082087" />
    </inertial>
    <visual>
      <origin
        xyz="0 0 0"
        rpy="0 0 0" />
      <geometry>
        <mesh
          filename="package://LiteParallelGriper9/meshes/Link4.STL" />
      </geometry>
      <material
        name="">
        <color
          rgba="0.792156862745098 0.819607843137255 0.933333333333333 1" />
      </material>
    </visual>
    <collision>
      <origin
        xyz="0 0 0"
        rpy="0 0 0" />
      <geometry>
        <mesh
          filename="package://LiteParallelGriper9/meshes/Link4.STL" />
      </geometry>
    </collision>
  </link>
  <joint
    name="Joint4"
    type="continuous">
    <origin
      xyz="-0.0705145150381237 -0.0870000000340616 -0.0363195600469317"
      rpy="0 0 0.869790175262033" />
    <parent
      link="Link3" />
    <child
      link="Link4" />
    <axis
      xyz="0 0 1" />
    <limit
      lower="-3.14"
      upper="3.14"
      effort="87"
      velocity="0.5" />
  </joint>
  <link
    name="Link5">
    <inertial>
      <origin
        xyz="0.00343403155541083 -2.36616388929467E-06 -0.0016448646110556"
        rpy="0 0 0" />
      <mass
        value="0.407437629747687" />
      <inertia
        ixx="0.000358679363012641"
        ixy="-9.48497692080804E-09"
        ixz="-6.27720628913369E-06"
        iyy="0.000380453387598683"
        iyz="9.95827271108431E-09"
        izz="0.000334587682435985" />
    </inertial>
    <visual>
      <origin
        xyz="0 0 0"
        rpy="0 0 0" />
      <geometry>
        <mesh
          filename="package://LiteParallelGriper9/meshes/Link5.STL" />
      </geometry>
      <material
        name="">
        <color
          rgba="0.792156862745098 0.819607843137255 0.933333333333333 1" />
      </material>
    </visual>
    <collision>
      <origin
        xyz="0 0 0"
        rpy="0 0 0" />
      <geometry>
        <mesh
          filename="package://LiteParallelGriper9/meshes/Link5.STL" />
      </geometry>
    </collision>
  </link>
  <joint
    name="Joint5"
    type="continuous">
    <origin
      xyz="0 0 -0.190790437043502"
      rpy="-0.666939521728903 0 0" />
    <parent
      link="Link4" />
    <child
      link="Link5" />
    <axis
      xyz="1 0 0" />
    <limit
      lower="-3.14"
      upper="3.14"
      effort="12"
      velocity="1" />
  </joint>
  <link
    name="Link6">
    <inertial>
      <origin
        xyz="0.000274183128525979 0.000417792805570888 -0.0521159235743316"
        rpy="0 0 0" />
      <mass
        value="0.0844259193061576" />
      <inertia
        ixx="3.65815393489733E-05"
        ixy="-2.96693328041841E-08"
        ixz="3.6264522907474E-08"
        iyy="3.63144343347605E-05"
        iyz="-6.16831241202342E-08"
        izz="6.56235022074535E-05" />
    </inertial>
    <visual>
      <origin
        xyz="0 0 0"
        rpy="0 0 0" />
      <geometry>
        <mesh
          filename="package://LiteParallelGriper9/meshes/Link6.STL" />
      </geometry>
      <material
        name="">
        <color
          rgba="0.792156862745098 0.819607843137255 0.933333333333333 1" />
      </material>
    </visual>
    <collision>
      <origin
        xyz="0 0 0"
        rpy="0 0 0" />
      <geometry>
        <mesh
          filename="package://LiteParallelGriper9/meshes/Link6.STL" />
      </geometry>
    </collision>
  </link>
  <joint
    name="Joint6"
    type="continuous">
    <origin
      xyz="0 0 0"
      rpy="0 0 -1.27776431199109" />
    <parent
      link="Link5" />
    <child
      link="Link6" />
    <axis
      xyz="0 0 1" />
    <limit
      lower="-3.14"
      upper="3.14"
      effort="12"
      velocity="1" />
  </joint>
  <link
    name="Link_hand">
    <inertial>
      <origin
        xyz="-0.00577010131191774 -6.63367727166131E-07 -0.0020449427041033"
        rpy="0 0 0" />
      <mass
        value="0.0615360469944409" />
      <inertia
        ixx="3.70361303346527E-05"
        ixy="4.66409878560795E-09"
        ixz="-2.12198750977682E-07"
        iyy="6.46528304039921E-05"
        iyz="6.05357565502379E-11"
        izz="7.92466350125759E-05" />
    </inertial>
    <visual>
      <origin
        xyz="0 0 0"
        rpy="0 0 0" />
      <geometry>
        <mesh
          filename="package://LiteParallelGriper9/meshes/Link_hand.STL" />
      </geometry>
      <material
        name="">
        <color
          rgba="0.627450980392157 0.627450980392157 0.627450980392157 1" />
      </material>
    </visual>
    <collision>
      <origin
        xyz="0 0 0"
        rpy="0 0 0" />
      <geometry>
        <mesh
          filename="package://LiteParallelGriper9/meshes/Link_hand.STL" />
      </geometry>
    </collision>
  </link>
  <joint
    name="Jointhand"
    type="fixed">
    <origin
      xyz="-0.0057852 -0.00043744 -0.115"
      rpy="-3.1416 0 -2.9883" />
    <parent
      link="Link6" />
    <child
      link="Link_hand" />
    <axis
      xyz="0 0 0" />
    <limit
      lower="0"
      effort="0"
      velocity="0" />
  </joint>
  <link
    name="F1">
    <inertial>
      <origin
        xyz="5.55111512312578E-17 -0.0363190407693183 -0.0253893461314733"
        rpy="0 0 0" />
      <mass
        value="0.00588455710912804" />
      <inertia
        ixx="1.74429173239014E-06"
        ixy="-5.02925812432241E-22"
        ixz="-2.64697796016969E-22"
        iyy="1.73702560834722E-07"
        iyz="1.17920315299786E-07"
        izz="1.82627225504684E-06" />
    </inertial>
    <visual>
      <origin
        xyz="0 0 0"
        rpy="0 0 0" />
      <geometry>
        <mesh
          filename="package://LiteParallelGriper9/meshes/F1.STL" />
      </geometry>
      <material
        name="">
        <color
          rgba="0.498039215686275 0.498039215686275 0.498039215686275 1" />
      </material>
    </visual>
    <collision>
      <origin
        xyz="0 0 0"
        rpy="0 0 0" />
      <geometry>
        <mesh
          filename="package://LiteParallelGriper9/meshes/F1.STL" />
      </geometry>
    </collision>
  </link>
  <joint
    name="Joint_f1"
    type="prismatic">
    <origin
      xyz="0.00016397 2.8968E-05 0.024562"
      rpy="-1.5708 0 1.5708" />
    <parent
      link="Link_hand" />
    <child
      link="F1" />
    <axis
      xyz="0 0 1" />
    <limit
      lower="0"
      upper="0.03"
      effort="200"
      velocity="0.1" />
    <dynamics
      damping="10"
      friction="0" />
  </joint>
  <link
    name="F1point">
    <inertial>
      <origin
        xyz="0 2.77555756156289E-17 0.000999999999999973"
        rpy="0 0 0" />
      <mass
        value="0.00013" />
      <inertia
        ixx="3.14166666666666E-10"
        ixy="5.23450231381213E-25"
        ixz="-3.21501839644634E-25"
        iyy="1.12666666666667E-09"
        iyz="8.27180612553028E-25"
        izz="1.35416666666667E-09" />
    </inertial>
    <visual>
      <origin
        xyz="0 0 0"
        rpy="0 0 0" />
      <geometry>
        <mesh
          filename="package://LiteParallelGriper9/meshes/F1point.STL" />
      </geometry>
      <material
        name="">
        <color
          rgba="0.498039215686275 0.498039215686275 0.498039215686275 1" />
      </material>
    </visual>
    <collision>
      <origin
        xyz="0 0 0"
        rpy="0 0 0" />
      <geometry>
        <mesh
          filename="package://LiteParallelGriper9/meshes/F1point.STL" />
      </geometry>
    </collision>
  </link>
  <joint
    name="f1_pjoint"
    type="fixed">
    <origin
      xyz="0 -0.053 -0.022236"
      rpy="3.1416 0 1.5708" />
    <parent
      link="F1" />
    <child
      link="F1point" />
    <axis
      xyz="0 0 0" />
  </joint>
  <link
    name="F2">
    <inertial>
      <origin
        xyz="5.55111512312578E-17 -0.0363190407693245 -0.0253893461314729"
        rpy="0 0 0" />
      <mass
        value="0.00588455710912804" />
      <inertia
        ixx="1.74429173239014E-06"
        ixy="-3.87120526674817E-22"
        ixz="1.58818677610181E-22"
        iyy="1.73702560834723E-07"
        iyz="1.17920315299788E-07"
        izz="1.82627225504684E-06" />
    </inertial>
    <visual>
      <origin
        xyz="0 0 0"
        rpy="0 0 0" />
      <geometry>
        <mesh
          filename="package://LiteParallelGriper9/meshes/F2.STL" />
      </geometry>
      <material
        name="">
        <color
          rgba="0.498039215686275 0.498039215686275 0.498039215686275 1" />
      </material>
    </visual>
    <collision>
      <origin
        xyz="0 0 0"
        rpy="0 0 0" />
      <geometry>
        <mesh
          filename="package://LiteParallelGriper9/meshes/F2.STL" />
      </geometry>
    </collision>
  </link>
  <joint
    name="Joint_f2"
    type="prismatic">
    <origin
      xyz="-0.012164 0 0.024562"
      rpy="-1.5708 0 -1.5708" />
    <parent
      link="Link_hand" />
    <child
      link="F2" />
    <axis
      xyz="0 0 1" />
    <limit
      lower="0"
      upper="0.03"
      effort="200"
      velocity="0.1" />
    <dynamics
      damping="10"
      friction="0" />
    <mimic
      joint="Joint_f1"
      multiplier="1"
      offset="0" />
  </joint>
  <link
    name="F2point">
    <inertial>
      <origin
        xyz="-2.77555756156289E-17 -2.77555756156289E-17 0.000999999999999973"
        rpy="0 0 0" />
      <mass
        value="0.00013" />
      <inertia
        ixx="3.14166666666668E-10"
        ixy="-4.13590306276514E-25"
        ixz="4.44286461820474E-26"
        iyy="1.12666666666667E-09"
        iyz="5.42837276987924E-25"
        izz="1.35416666666667E-09" />
    </inertial>
    <visual>
      <origin
        xyz="0 0 0"
        rpy="0 0 0" />
      <geometry>
        <mesh
          filename="package://LiteParallelGriper9/meshes/F2point.STL" />
      </geometry>
      <material
        name="">
        <color
          rgba="0.498039215686275 0.498039215686275 0.498039215686275 1" />
      </material>
    </visual>
    <collision>
      <origin
        xyz="0 0 0"
        rpy="0 0 0" />
      <geometry>
        <mesh
          filename="package://LiteParallelGriper9/meshes/F2point.STL" />
      </geometry>
    </collision>
  </link>
  <joint
    name="f2_pjoint"
    type="fixed">
    <origin
      xyz="0 -0.053 -0.022236"
      rpy="-3.1416 0 1.5708" />
    <parent
      link="F2" />
    <child
      link="F2point" />
    <axis
      xyz="0 0 0" />
  </joint>
  <link
    name="GripSite">
    <inertial>
      <origin
        xyz="-1.66533453693773E-16 -4.16333634234434E-16 5.82867087928207E-16"
        rpy="0 0 0" />
      <mass
        value="0.000523598775598299" />
      <inertia
        ixx="5.23598775598299E-09"
        ixy="1.55096364853693E-25"
        ixz="4.13590306276514E-25"
        iyy="5.23598775598299E-09"
        iyz="1.03397576569128E-25"
        izz="5.23598775598299E-09" />
    </inertial>
    <visual>
      <origin
        xyz="0 0 0"
        rpy="0 0 0" />
      <geometry>
        <mesh
          filename="package://LiteParallelGriper9/meshes/GripSite.STL" />
      </geometry>
      <material
        name="">
        <color
          rgba="0.792156862745098 0.819607843137255 0.933333333333333 1" />
      </material>
    </visual>
  </link>
  <joint
    name="gripjoint"
    type="fixed">
    <origin
      xyz="-0.006 0 0.077562"
      rpy="-1.1646 -0.33468 -2.3203" />
    <parent
      link="Link_hand" />
    <child
      link="GripSite" />
    <axis
      xyz="0 0 0" />
  </joint>
</robot>